[2023-12-10 02:51:01,126: INFO/MainProcess] Connected to redis://:**@redis:6379/0
[2023-12-10 02:51:01,134: INFO/MainProcess] mingle: searching for neighbors
[2023-12-10 02:51:02,148: INFO/MainProcess] mingle: all alone
[2023-12-10 02:51:02,160: INFO/MainProcess] celery@97ddb40c288e ready.
[2023-12-10 02:51:31,503: WARNING/MainProcess] consumer: Connection to broker lost. Trying to re-establish the connection...
Traceback (most recent call last):
  File "/usr/local/lib/python2.7/dist-packages/celery/worker/consumer/consumer.py", line 316, in start
    blueprint.start(self)
  File "/usr/local/lib/python2.7/dist-packages/celery/bootsteps.py", line 119, in start
    step.start(parent)
  File "/usr/local/lib/python2.7/dist-packages/celery/worker/consumer/consumer.py", line 592, in start
    c.loop(*c.loop_args())
  File "/usr/local/lib/python2.7/dist-packages/celery/worker/loops.py", line 91, in asynloop
    next(loop)
  File "/usr/local/lib/python2.7/dist-packages/kombu/asynchronous/hub.py", line 364, in create_loop
    cb(*cbargs)
  File "/usr/local/lib/python2.7/dist-packages/kombu/transport/redis.py", line 1088, in on_readable
    self.cycle.on_readable(fileno)
  File "/usr/local/lib/python2.7/dist-packages/kombu/transport/redis.py", line 359, in on_readable
    chan.handlers[type]()
  File "/usr/local/lib/python2.7/dist-packages/kombu/transport/redis.py", line 693, in _receive
    ret.append(self._receive_one(c))
  File "/usr/local/lib/python2.7/dist-packages/kombu/transport/redis.py", line 703, in _receive_one
    response = c.parse_response()
  File "/usr/local/lib/python2.7/dist-packages/redis/client.py", line 3453, in parse_response
    response = self._execute(conn, conn.read_response)
  File "/usr/local/lib/python2.7/dist-packages/redis/client.py", line 3427, in _execute
    return command(*args, **kwargs)
  File "/usr/local/lib/python2.7/dist-packages/redis/connection.py", line 734, in read_response
    response = self._parser.read_response()
  File "/usr/local/lib/python2.7/dist-packages/redis/connection.py", line 316, in read_response
    response = self._buffer.readline()
  File "/usr/local/lib/python2.7/dist-packages/redis/connection.py", line 248, in readline
    self._read_from_socket()
  File "/usr/local/lib/python2.7/dist-packages/redis/connection.py", line 193, in _read_from_socket
    raise ConnectionError(SERVER_CLOSED_CONNECTION_ERROR)
ConnectionError: Connection closed by server.
[2023-12-10 02:51:35,660: ERROR/MainProcess] consumer: Cannot connect to redis://:**@redis:6379/0: Error -2 connecting to redis:6379. Name or service not known..
Trying again in 2.00 seconds...

[2023-12-10 02:51:37,672: ERROR/MainProcess] consumer: Cannot connect to redis://:**@redis:6379/0: Error -2 connecting to redis:6379. Name or service not known..
Trying again in 4.00 seconds...

[2023-12-10 02:51:42,351: ERROR/MainProcess] consumer: Cannot connect to redis://:**@redis:6379/0: Error -2 connecting to redis:6379. Name or service not known..
Trying again in 2.00 seconds...

[2023-12-10 02:51:44,357: INFO/MainProcess] Connected to redis://:**@redis:6379/0
[2023-12-10 02:51:44,365: INFO/MainProcess] mingle: searching for neighbors
[2023-12-10 02:51:45,381: INFO/MainProcess] mingle: all alone
[2023-12-10 02:51:45,391: INFO/MainProcess] celery@e423f5406abe ready.
[2023-12-10 03:01:04,997: WARNING/MainProcess] consumer: Connection to broker lost. Trying to re-establish the connection...
Traceback (most recent call last):
  File "/usr/local/lib/python2.7/dist-packages/celery/worker/consumer/consumer.py", line 316, in start
    blueprint.start(self)
  File "/usr/local/lib/python2.7/dist-packages/celery/bootsteps.py", line 119, in start
    step.start(parent)
  File "/usr/local/lib/python2.7/dist-packages/celery/worker/consumer/consumer.py", line 592, in start
    c.loop(*c.loop_args())
  File "/usr/local/lib/python2.7/dist-packages/celery/worker/loops.py", line 91, in asynloop
    next(loop)
  File "/usr/local/lib/python2.7/dist-packages/kombu/asynchronous/hub.py", line 364, in create_loop
    cb(*cbargs)
  File "/usr/local/lib/python2.7/dist-packages/kombu/transport/redis.py", line 1088, in on_readable
    self.cycle.on_readable(fileno)
  File "/usr/local/lib/python2.7/dist-packages/kombu/transport/redis.py", line 359, in on_readable
    chan.handlers[type]()
  File "/usr/local/lib/python2.7/dist-packages/kombu/transport/redis.py", line 693, in _receive
    ret.append(self._receive_one(c))
  File "/usr/local/lib/python2.7/dist-packages/kombu/transport/redis.py", line 703, in _receive_one
    response = c.parse_response()
  File "/usr/local/lib/python2.7/dist-packages/redis/client.py", line 3453, in parse_response
    response = self._execute(conn, conn.read_response)
  File "/usr/local/lib/python2.7/dist-packages/redis/client.py", line 3427, in _execute
    return command(*args, **kwargs)
  File "/usr/local/lib/python2.7/dist-packages/redis/connection.py", line 734, in read_response
    response = self._parser.read_response()
  File "/usr/local/lib/python2.7/dist-packages/redis/connection.py", line 316, in read_response
    response = self._buffer.readline()
  File "/usr/local/lib/python2.7/dist-packages/redis/connection.py", line 248, in readline
    self._read_from_socket()
  File "/usr/local/lib/python2.7/dist-packages/redis/connection.py", line 193, in _read_from_socket
    raise ConnectionError(SERVER_CLOSED_CONNECTION_ERROR)
ConnectionError: Connection closed by server.
[2023-12-10 03:01:09,115: INFO/MainProcess] Connected to redis://:**@redis:6379/0
[2023-12-10 03:01:09,121: INFO/MainProcess] mingle: searching for neighbors
[2023-12-10 03:01:10,126: INFO/MainProcess] mingle: all alone
[2023-12-10 03:01:17,893: INFO/MainProcess] Connected to redis://:**@redis:6379/0
[2023-12-10 03:01:17,899: INFO/MainProcess] mingle: searching for neighbors
[2023-12-10 03:01:18,914: INFO/MainProcess] mingle: all alone
[2023-12-10 03:01:18,929: INFO/MainProcess] celery@76849316bea1 ready.
